================================================================================
                    ERROR FORMAT COMPARISON
================================================================================

❌ WHAT YOU HAVE (Won't work - Runtime Error)
────────────────────────────────────────────────────────────────────────────

Traceback (most recent call last):
  File "/app/services/logging_service.py", line 160, in _send_to_remote_sync
    return self.logs_collector_client.send(log_entry)
           ^^^^^^^^^^^^^^^^^^^^^^^^^^^^^^^^^^^^^^^^^^
  File "/usr/local/lib/python3.11/unittest/mock.py", line 1124, in __call__
    return self._mock_call(*args, **kwargs)
Exception: Timeout

Problems:
  ❌ First line is in services/ (not tests/)
  ❌ No test method name visible
  ❌ No "in test_" pattern found
  ❌ Script can't identify which test to fix
  ❌ Script will SKIP this error

Result: "⚠ Skipping error - cannot identify test file/method"

================================================================================

✅ WHAT YOU NEED (Will work - Test Method Error)
────────────────────────────────────────────────────────────────────────────

Traceback (most recent call last):
  File "/app/tests/test_account_category_service.py", line 97, in test_create_or_update_account
    account1 = self.service.create_or_update_account(self.test_email)
               ^^^^^^^^^^^^^^^^^^^^^^^^^^^^^^^^^^^^^
AttributeError: 'AccountCategoryClient' object has no attribute 'create_or_update_account'

Extracted Info:
  ✅ Test file: tests/test_account_category_service.py
  ✅ Test method: test_create_or_update_account
  ✅ Error type: AttributeError
  ✅ Line number: 97
  ✅ Pytest command: python -m pytest tests/test_account_category_service.py::test_create_or_update_account -v

Result: "✓ Successfully fixed: tests/test_account_category_service.py::test_create_or_update_account"

================================================================================

HOW TO CHECK YOUR FILE
────────────────────────────────────────────────────────────────────────────

    ./check_error_file.sh errors.txt

Your results:
    ❌ No test file references
    ❌ No test method references
    Conclusion: File needs to be regenerated

Sample file results:
    ✅ Found 3 test file references
    ✅ Found 2 test method references
    Conclusion: File is ready to use!

================================================================================

QUICK FIX
────────────────────────────────────────────────────────────────────────────

# Generate new error file
python3 -m pytest tests/ -v 2>&1 | python3 extract_test_errors.py > new_errors.txt

# Check it
./check_error_file.sh new_errors.txt

# Use it (if checks pass)
python3 fix_test_errors.py new_errors.txt --model sonnet

================================================================================
